<robot
  name="ar3">
  <link
    name="base_link">
    <inertial>
      <origin
        xyz="-4.6941E-06 0.054174 0.038824"
        rpy="0 0 0" />
      <mass
        value="0.7102" />
      <inertia
        ixx="0.0039943"
        ixy="3.697E-07"
        ixz="-5.7364E-08"
        iyy="0.0014946"
        iyz="-0.00036051"
        izz="0.0042554" />
    </inertial>
    <visual>
      <origin
        xyz="0 0 0"
        rpy="0 0 0" />
      <geometry>
        <mesh
          filename="package://ar3_description/meshes/base_link.STL" />
      </geometry>
      <material
        name="">
        <color
          rgba="1 1 0 1" />
      </material>
    </visual>
    <collision>
      <origin
        xyz="0 0 0"
        rpy="0 0 0" />
      <geometry>
        <mesh
          filename="package://ar3_description/meshes/base_link.STL" />
      </geometry>
    </collision>
  </link>
  <link
    name="link_1">
    <inertial>
      <origin
        xyz="-0.022706 0.04294 -0.12205"
        rpy="0 0 0" />
      <mass
        value="0.88065" />
      <inertia
        ixx="0.0034"
        ixy="0.00042296"
        ixz="-0.00089231"
        iyy="0.0041778"
        iyz="0.0010848"
        izz="0.0027077" />
    </inertial>
    <visual>
      <origin
        xyz="0 0 0"
        rpy="0 0 0" />
      <geometry>
        <mesh
          filename="package://ar3_description/meshes/link_1.STL" />
      </geometry>
      <material
        name="">
        <color
          rgba="1 1 0 1" />
      </material>
    </visual>
    <collision>
      <origin
        xyz="0 0 0"
        rpy="0 0 0" />
      <geometry>
        <mesh
          filename="package://ar3_description/meshes/link_1.STL" />
      </geometry>
    </collision>
  </link>
  <joint
    name="joint_1"
    type="continuous">
    <origin
      xyz="0 0 0.003445"
      rpy="3.1416 -1.0248E-21 -1.6736E-05" />
    <parent
      link="base_link" />
    <child
      link="link_1" />
    <axis
      xyz="0 0 1" />
  </joint>
  <link
    name="link_2">
    <inertial>
      <origin
        xyz="0.064818 -0.11189 -0.038671"
        rpy="0 0 0" />
      <mass
        value="0.57738" />
      <inertia
        ixx="0.0047312"
        ixy="0.0022624"
        ixz="0.00032144"
        iyy="0.0020836"
        iyz="-0.00056569"
        izz="0.0056129" />
    </inertial>
    <visual>
      <origin
        xyz="0 0 0"
        rpy="0 0 0" />
      <geometry>
        <mesh
          filename="package://ar3_description/meshes/link_2.STL" />
      </geometry>
      <material
        name="">
        <color
          rgba="1 1 0 1" />
      </material>
    </visual>
    <collision>
      <origin
        xyz="0 0 0"
        rpy="0 0 0" />
      <geometry>
        <mesh
          filename="package://ar3_description/meshes/link_2.STL" />
      </geometry>
    </collision>
  </link>
  <joint
    name="joint_2"
    type="continuous">
    <origin
      xyz="0 0.064146 -0.16608"
      rpy="1.5708 0.5236 -1.5708" />
    <parent
      link="link_1" />
    <child
      link="link_2" />
    <axis
      xyz="0 0 -1" />
  </joint>
  <link
    name="link_3">
    <inertial>
      <origin
        xyz="-0.00029765 -0.023661 -1.04720367321"
        rpy="0 0 0" />
      <mass
        value="0.1787" />
      <inertia
        ixx="0.0001685"
        ixy="-2.7713E-05"
        ixz="5.6885E-06"
        iyy="0.00012865"
        iyz="2.9256E-05"
        izz="0.00020744" />
    </inertial>
    <visual>
      <origin
        xyz="0 0 0"
        rpy="0 0 0" />
      <geometry>
        <mesh
          filename="package://ar3_description/meshes/link_3.STL" />
      </geometry>
      <material
        name="">
        <color
          rgba="1 1 0 1" />
      </material>
    </visual>
    <collision>
      <origin
        xyz="0 0 0"
        rpy="0 0 0" />
      <geometry>
        <mesh
          filename="package://ar3_description/meshes/link_3.STL" />
      </geometry>
    </collision>
  </link>
  <joint
    name="joint_3"
    type="continuous">
    <origin
      xyz="0.1525 -0.26414 0"
      rpy="3.3431E-16 -1.4164E-16 -1.4953816339" />
    <parent
      link="link_2" />
    <child
      link="link_3" />
    <axis
      xyz="0 0 -1" />
  </joint>
  <link
    name="link_4">
    <inertial>
      <origin
        xyz="-0.0016798 -0.00057319 -0.074404"
        rpy="0 0 0" />
      <mass
        value="0.34936" />
      <inertia
        ixx="0.0030532"
        ixy="-1.8615E-05"
        ixz="-7.0047E-05"
        iyy="0.0031033"
        iyz="-2.3301E-05"
        izz="0.00022264" />
    </inertial>
    <visual>
      <origin
        xyz="0 0 0"
        rpy="0 0 0" />
      <geometry>
        <mesh
          filename="package://ar3_description/meshes/link_4.STL" />
      </geometry>
      <material
        name="">
        <color
          rgba="1 1 0 1" />
      </material>
    </visual>
    <collision>
      <origin
        xyz="0 0 0"
        rpy="0 0 0" />
      <geometry>
        <mesh
          filename="package://ar3_description/meshes/link_4.STL" />
      </geometry>
    </collision>
  </link>
  <joint
    name="joint_4"
    type="continuous">
    <origin
      xyz="0 0 0.00675"
      rpy="1.5708 -1.2554 -1.5708" />
    <parent
      link="link_3" />
    <child
      link="link_4" />
    <axis
      xyz="0 0 -1" />
  </joint>
  <link
    name="link_5">
    <inertial>
      <origin
        xyz="0.0015066 -1.3102E-05 -0.012585"
        rpy="0 0 0" />
      <mass
        value="0.11562" />
      <inertia
        ixx="5.5035E-05"
        ixy="-1.019E-08"
        ixz="-2.6243E-06"
        iyy="8.2921E-05"
        iyz="1.4437E-08"
        izz="5.2518E-05" />
    </inertial>
    <visual>
      <origin
        xyz="0 0 0"
        rpy="0 0 0" />
      <geometry>
        <mesh
          filename="package://ar3_description/meshes/link_5.STL" />
      </geometry>
      <material
        name="">
        <color
          rgba="1 1 0 1" />
      </material>
    </visual>
    <collision>
      <origin
        xyz="0 0 0"
        rpy="0 0 0" />
      <geometry>
        <mesh
          filename="package://ar3_description/meshes/link_5.STL" />
      </geometry>
    </collision>
  </link>
  <joint
    name="joint_5"
    type="continuous">
    <origin
      xyz="0 0 -0.22225"
      rpy="3.1416 0 -2.8262" />
    <parent
      link="link_4" />
    <child
      link="link_5" />
    <axis
      xyz="-1 0 0" />
  </joint>
  <link
    name="link_6">
    <inertial>
      <origin
        xyz="2.9287E-10 -1.6472E-09 0.0091432"
        rpy="0 0 0" />
      <mass
        value="0.013863" />
      <inertia
        ixx="1.3596E-06"
        ixy="3.0585E-13"
        ixz="5.7102E-14"
        iyy="1.7157E-06"
        iyz="6.3369E-09"
        izz="2.4332E-06" />
    </inertial>
    <visual>
      <origin
        xyz="0 0 0"
        rpy="0 0 0" />
      <geometry>
        <mesh
          filename="package://ar3_description/meshes/link_6.STL" />
      </geometry>
      <material
        name="">
        <color
          rgba="1 1 0 1" />
      </material>
    </visual>
    <collision>
      <origin
        xyz="0 0 0"
        rpy="0 0 0" />
      <geometry>
        <mesh
          filename="package://ar3_description/meshes/link_6.STL" />
      </geometry>
    </collision>
  </link>
  <joint
    name="joint_6"
    type="continuous">
    <origin
      xyz="-0.000294 0 0.02117"
      rpy="0 0 3.1416" />
    <parent
      link="link_5" />
    <child
      link="link_6" />
    <axis
      xyz="0 0 1" />
  </joint>
    
    <link
    name="gripper_base_link">
    <inertial>
      <origin
        xyz="0.000201676352247788 -0.000271374020595348 0.0205764880482399"
        rpy="0 0 0" />
      <mass
        value="0.0837131933946375" />
      <inertia
        ixx="1.27397176956936E-05"
        ixy="-1.92472475737929E-07"
        ixz="-2.59961702797386E-07"
        iyy="3.03147660705332E-05"
        iyz="-4.38487554539977E-07"
        izz="3.76673423663697E-05" />
    </inertial>
    <visual>
      <origin
        xyz="0 0 0"
        rpy="0 0 0" />
      <geometry>
        <mesh
          filename="package://ar3_description/meshes/gripper_base_link.STL" />
      </geometry>
      <material
        name="">
        <color
          rgba="0.792156862745098 0.819607843137255 0.933333333333333 1" />
      </material>
    </visual>
    <collision>
      <origin
        xyz="0 0 0"
        rpy="0 0 0" />
      <geometry>
        <mesh
          filename="package://ar3_description/meshes/gripper_base_link.STL" />
      </geometry>
    </collision>
  </link>
  <joint
    name="joint_7"
    type="fixed">
    <origin
      xyz="-0.000294 0 0.0162"
      rpy="-1.57 0 0" />
    <parent
      link="link_6" />
    <child
      link="gripper_base_link" />
    <axis
      xyz="0 0 1" />
  </joint>

  <link
    name="left_gripper">
    <inertial>
      <origin
        xyz="-0.0195202213701238 0.0103863936746414 0.0109639611383669"
        rpy="0 0 0" />
      <mass
        value="0.00654748908133538" />
      <inertia
        ixx="8.84676970462487E-07"
        ixy="7.1930007360712E-08"
        ixz="1.95149753842345E-08"
        iyy="6.07697846024335E-07"
        iyz="-1.59781110867253E-07"
        izz="7.00611450389647E-07" />
    </inertial>
    <visual>
      <origin
        xyz="0 0 0"
        rpy="0 0 0" />
      <geometry>
        <mesh
          filename="package://ar3_description/meshes/left_gripper.STL" />
      </geometry>
      <material
        name="">
        <color
          rgba="0.250980392156863 0.250980392156863 0.250980392156863 1" />
      </material>
    </visual>
    <collision>
      <origin
        xyz="0 0 0"
        rpy="0 0 0" />
      <geometry>
        <mesh
          filename="package://ar3_description/meshes/left_gripper.STL" />
      </geometry>
    </collision>
  </link>
  <joint
    name="leftGripper"
    type="prismatic">
    <origin
      xyz="0 -0.035575 -0.015225"
      rpy="1.5708 0 0" />
    <parent
      link="gripper_base_link" />
    <child
      link="left_gripper" />
    <axis
      xyz="1 0 0" />
    <limit
      lower="0"
      upper="0"
      effort="0"
      velocity="0" />
  </joint>

  <link
    name="right_Gripper">
    <inertial>
      <origin
        xyz="-0.0187964103588927 0.0105172601371314 0.0110527863050884"
        rpy="0 0 0" />
      <mass
        value="0.00651398591885153" />
      <inertia
        ixx="8.60320633970985E-07"
        ixy="7.39519862508087E-08"
        ixz="2.08874041010245E-08"
        iyy="5.94973791276392E-07"
        iyz="-1.48265837261608E-07"
        izz="6.78016327392414E-07" />
    </inertial>
    <visual>
      <origin
        xyz="0 0 0"
        rpy="0 0 0" />
      <geometry>
        <mesh
          filename="package://ar3_description/meshes/right_Gripper.STL" />
      </geometry>
      <material
        name="">
        <color
          rgba="0.250980392156863 0.250980392156863 0.250980392156863 1" />
      </material>
    </visual>
    <collision>
      <origin
        xyz="0 0 0"
        rpy="0 0 0" />
      <geometry>
        <mesh
          filename="package://ar3_description/meshes/right_Gripper.STL" />
      </geometry>
    </collision>
  </link>
  <joint
    name="rightGripper"
    type="prismatic">
    <origin
      xyz="0 -0.035575 0.009925"
      rpy="-1.5708 0 3.1416" />
    <parent
      link="gripper_base_link" />
    <child
      link="right_Gripper" />
    <axis
      xyz="1 0 0" />
    <limit
      lower="0"
      upper="0"
      effort="0"
      velocity="0" />
  </joint>
</robot>